[2023-12-22T14:12:43.635-0300] {taskinstance.py:1957} INFO - Dependencies all met for dep_context=non-requeueable deps ti=<TaskInstance: model_adventureworks_sales_category.checks_ingest manual__2023-12-22T17:07:22.167736+00:00 [queued]>
[2023-12-22T14:12:43.638-0300] {taskinstance.py:1957} INFO - Dependencies all met for dep_context=requeueable deps ti=<TaskInstance: model_adventureworks_sales_category.checks_ingest manual__2023-12-22T17:07:22.167736+00:00 [queued]>
[2023-12-22T14:12:43.638-0300] {taskinstance.py:2171} INFO - Starting attempt 2 of 2
[2023-12-22T14:12:43.794-0300] {taskinstance.py:2192} INFO - Executing <Task(PythonVirtualenvOperator): checks_ingest> on 2023-12-22 17:07:22.167736+00:00
[2023-12-22T14:12:43.798-0300] {standard_task_runner.py:60} INFO - Started process 83447 to run task
[2023-12-22T14:12:43.801-0300] {standard_task_runner.py:87} INFO - Running: ['airflow', 'tasks', 'run', 'model_adventureworks_sales_category', 'checks_ingest', 'manual__2023-12-22T17:07:22.167736+00:00', '--job-id', '36', '--raw', '--subdir', 'DAGS_FOLDER/model_sales_category.py', '--cfg-path', '/tmp/tmp7z7de0__']
[2023-12-22T14:12:43.802-0300] {standard_task_runner.py:88} INFO - Job 36: Subtask checks_ingest
[2023-12-22T14:12:44.082-0300] {task_command.py:423} INFO - Running <TaskInstance: model_adventureworks_sales_category.checks_ingest manual__2023-12-22T17:07:22.167736+00:00 [running]> on host franco-MS-7B84
[2023-12-22T14:12:44.468-0300] {taskinstance.py:2481} INFO - Exporting env vars: AIRFLOW_CTX_DAG_OWNER='soda_core' AIRFLOW_CTX_DAG_ID='model_adventureworks_sales_category' AIRFLOW_CTX_TASK_ID='checks_ingest' AIRFLOW_CTX_EXECUTION_DATE='2023-12-22T17:07:22.167736+00:00' AIRFLOW_CTX_TRY_NUMBER='2' AIRFLOW_CTX_DAG_RUN_ID='manual__2023-12-22T17:07:22.167736+00:00'
[2023-12-22T14:12:44.470-0300] {process_utils.py:182} INFO - Executing cmd: /home/franco/Documents/Projects/soda/.venv/bin/python -m virtualenv /tmp/venva4toiiur --python=python
[2023-12-22T14:12:44.470-0300] {process_utils.py:186} INFO - Output:
[2023-12-22T14:12:44.763-0300] {process_utils.py:190} INFO - created virtual environment CPython3.10.12.final.0-64 in 229ms
[2023-12-22T14:12:44.763-0300] {process_utils.py:190} INFO -   creator CPython3Posix(dest=/tmp/venva4toiiur, clear=False, no_vcs_ignore=False, global=False)
[2023-12-22T14:12:44.763-0300] {process_utils.py:190} INFO -   seeder FromAppData(download=False, pip=bundle, setuptools=bundle, wheel=bundle, via=copy, app_data_dir=/home/franco/.local/share/virtualenv)
[2023-12-22T14:12:44.763-0300] {process_utils.py:190} INFO -     added seed packages: pip==23.3.2, setuptools==69.0.2, wheel==0.42.0
[2023-12-22T14:12:44.763-0300] {process_utils.py:190} INFO -   activators BashActivator,CShellActivator,FishActivator,NushellActivator,PowerShellActivator,PythonActivator
[2023-12-22T14:12:44.775-0300] {process_utils.py:182} INFO - Executing cmd: /tmp/venva4toiiur/bin/pip install -r /tmp/venva4toiiur/requirements.txt
[2023-12-22T14:12:44.775-0300] {process_utils.py:186} INFO - Output:
[2023-12-22T14:12:45.746-0300] {process_utils.py:190} INFO - ERROR: Could not find a version that satisfies the requirement soda-postgres (from versions: none)
[2023-12-22T14:12:45.746-0300] {process_utils.py:190} INFO - ERROR: No matching distribution found for soda-postgres
[2023-12-22T14:12:46.797-0300] {taskinstance.py:2699} ERROR - Task failed with exception
Traceback (most recent call last):
  File "/home/franco/Documents/Projects/soda/.venv/lib/python3.10/site-packages/airflow/models/taskinstance.py", line 433, in _execute_task
    result = execute_callable(context=context, **execute_callable_kwargs)
  File "/home/franco/Documents/Projects/soda/.venv/lib/python3.10/site-packages/airflow/operators/python.py", line 400, in execute
    return super().execute(context=serializable_context)
  File "/home/franco/Documents/Projects/soda/.venv/lib/python3.10/site-packages/airflow/operators/python.py", line 199, in execute
    return_value = self.execute_callable()
  File "/home/franco/Documents/Projects/soda/.venv/lib/python3.10/site-packages/airflow/operators/python.py", line 711, in execute_callable
    self._prepare_venv(tmp_path)
  File "/home/franco/Documents/Projects/soda/.venv/lib/python3.10/site-packages/airflow/operators/python.py", line 623, in _prepare_venv
    prepare_virtualenv(
  File "/home/franco/Documents/Projects/soda/.venv/lib/python3.10/site-packages/airflow/utils/python_virtualenv.py", line 118, in prepare_virtualenv
    execute_in_subprocess(pip_cmd)
  File "/home/franco/Documents/Projects/soda/.venv/lib/python3.10/site-packages/airflow/utils/process_utils.py", line 171, in execute_in_subprocess
    execute_in_subprocess_with_kwargs(cmd, cwd=cwd)
  File "/home/franco/Documents/Projects/soda/.venv/lib/python3.10/site-packages/airflow/utils/process_utils.py", line 194, in execute_in_subprocess_with_kwargs
    raise subprocess.CalledProcessError(exit_code, cmd)
subprocess.CalledProcessError: Command '['/tmp/venva4toiiur/bin/pip', 'install', '-r', '/tmp/venva4toiiur/requirements.txt']' returned non-zero exit status 1.
[2023-12-22T14:12:46.801-0300] {taskinstance.py:1138} INFO - Marking task as FAILED. dag_id=model_adventureworks_sales_category, task_id=checks_ingest, execution_date=20231222T170722, start_date=20231222T171243, end_date=20231222T171246
[2023-12-22T14:12:47.085-0300] {standard_task_runner.py:107} ERROR - Failed to execute job 36 for task checks_ingest (Command '['/tmp/venva4toiiur/bin/pip', 'install', '-r', '/tmp/venva4toiiur/requirements.txt']' returned non-zero exit status 1.; 83447)
[2023-12-22T14:12:47.098-0300] {local_task_job_runner.py:234} INFO - Task exited with return code 1
[2023-12-22T14:12:47.111-0300] {taskinstance.py:3281} INFO - 0 downstream tasks scheduled from follow-on schedule check
